schematic = {
	size = {x=11, y=12, z=11},
	yslice_prob = {
		{ypos=0, prob=254},
		{ypos=1, prob=254},
		{ypos=2, prob=254},
		{ypos=3, prob=254},
		{ypos=4, prob=254},
		{ypos=5, prob=254},
		{ypos=6, prob=254},
		{ypos=7, prob=254},
		{ypos=8, prob=254},
		{ypos=9, prob=254},
		{ypos=10, prob=254},
		{ypos=11, prob=254},
	},
	data = {
		{name="air", prob=0, param2=0},
		{name="air", prob=0, param2=0},
		{name="air", prob=0, param2=0},
		{name="air", prob=0, param2=0},
		{name="air", prob=0, param2=0},
		{name="air", prob=0, param2=0},
		{name="air", prob=0, param2=0},
		{name="air", prob=0, param2=0},
		{name="air", prob=0, param2=0},
		{name="air", prob=0, param2=0},
		{name="air", prob=0, param2=0},
		{name="air", prob=0, param2=0},
		{name="air", prob=0, param2=0},
		{name="air", prob=0, param2=0},
		{name="air", prob=0, param2=0},
		{name="air", prob=0, param2=0},
		{name="air", prob=0, param2=0},
		{name="air", prob=0, param2=0},
		{name="air", prob=0, param2=0},
		{name="air", prob=0, param2=0},
		{name="air", prob=0, param2=0},
		{name="air", prob=0, param2=0},
		{name="air", prob=0, param2=0},
		{name="air", prob=0, param2=0},
		{name="air", prob=0, param2=0},
		{name="air", prob=0, param2=0},
		{name="air", prob=0, param2=0},
		{name="air", prob=0, param2=0},
		{name="air", prob=0, param2=0},
		{name="air", prob=0, param2=0},
		{name="air", prob=0, param2=0},
		{name="air", prob=0, param2=0},
		{name="air", prob=0, param2=0},
		{name="air", prob=0, param2=0},
		{name="air", prob=0, param2=0},
		{name="air", prob=0, param2=0},
		{name="air", prob=0, param2=0},
		{name="air", prob=0, param2=0},
		{name="air", prob=0, param2=0},
		{name="air", prob=0, param2=0},
		{name="air", prob=0, param2=0},
		{name="air", prob=0, param2=0},
		{name="air", prob=0, param2=0},
		{name="air", prob=0, param2=0},
		{name="air", prob=0, param2=0},
		{name="air", prob=0, param2=0},
		{name="air", prob=0, param2=0},
		{name="air", prob=0, param2=0},
		{name="air", prob=0, param2=0},
		{name="air", prob=0, param2=0},
		{name="air", prob=0, param2=0},
		{name="air", prob=0, param2=0},
		{name="air", prob=0, param2=0},
		{name="air", prob=0, param2=0},
		{name="air", prob=0, param2=0},
		{name="air", prob=0, param2=0},
		{name="air", prob=0, param2=0},
		{name="air", prob=0, param2=0},
		{name="air", prob=0, param2=0},
		{name="air", prob=0, param2=0},
		{name="air", prob=0, param2=0},
		{name="air", prob=0, param2=0},
		{name="air", prob=0, param2=0},
		{name="air", prob=0, param2=0},
		{name="air", prob=0, param2=0},
		{name="air", prob=0, param2=0},
		{name="air", prob=0, param2=0},
		{name="air", prob=0, param2=0},
		{name="air", prob=0, param2=0},
		{name="mini_nodes:oak_leaves", prob=128, param2=0},
		{name="mini_nodes:oak_leaves", prob=128, param2=0},
		{name="mini_nodes:oak_leaves", prob=128, param2=0},
		{name="air", prob=0, param2=0},
		{name="air", prob=0, param2=0},
		{name="air", prob=0, param2=0},
		{name="air", prob=0, param2=0},
		{name="air", prob=0, param2=0},
		{name="air", prob=0, param2=0},
		{name="air", prob=0, param2=0},
		{name="air", prob=0, param2=0},
		{name="mini_nodes:oak_leaves", prob=128, param2=0},
		{name="mini_nodes:oak_leaves", prob=128, param2=0},
		{name="mini_nodes:oak_leaves", prob=254, param2=0},
		{name="mini_nodes:oak_leaves", prob=128, param2=0},
		{name="mini_nodes:oak_leaves", prob=128, param2=0},
		{name="air", prob=0, param2=0},
		{name="air", prob=0, param2=0},
		{name="air", prob=0, param2=0},
		{name="air", prob=0, param2=0},
		{name="air", prob=0, param2=0},
		{name="air", prob=0, param2=0},
		{name="mini_nodes:oak_leaves", prob=128, param2=0},
		{name="mini_nodes:oak_leaves", prob=128, param2=0},
		{name="mini_nodes:apple_leaves", prob=128, param2=0},
		{name="mini_nodes:oak_leaves", prob=254, param2=0},
		{name="air", prob=0, param2=0},
		{name="air", prob=0, param2=0},
		{name="air", prob=0, param2=0},
		{name="air", prob=0, param2=0},
		{name="air", prob=0, param2=0},
		{name="air", prob=0, param2=0},
		{name="air", prob=0, param2=0},
		{name="mini_nodes:apple_leaves", prob=128, param2=0},
		{name="mini_nodes:oak_leaves", prob=128, param2=0},
		{name="mini_nodes:oak_leaves", prob=128, param2=0},
		{name="air", prob=0, param2=0},
		{name="air", prob=0, param2=0},
		{name="air", prob=0, param2=0},
		{name="air", prob=0, param2=0},
		{name="air", prob=0, param2=0},
		{name="air", prob=0, param2=0},
		{name="air", prob=0, param2=0},
		{name="air", prob=0, param2=0},
		{name="air", prob=0, param2=0},
		{name="air", prob=0, param2=0},
		{name="air", prob=0, param2=0},
		{name="air", prob=0, param2=0},
		{name="air", prob=0, param2=0},
		{name="air", prob=0, param2=0},
		{name="air", prob=0, param2=0},
		{name="air", prob=0, param2=0},
		{name="air", prob=0, param2=0},
		{name="air", prob=0, param2=0},
		{name="air", prob=0, param2=0},
		{name="air", prob=0, param2=0},
		{name="air", prob=0, param2=0},
		{name="air", prob=0, param2=0},
		{name="air", prob=0, param2=0},
		{name="air", prob=0, param2=0},
		{name="air", prob=0, param2=0},
		{name="air", prob=0, param2=0},
		{name="air", prob=0, param2=0},
		{name="air", prob=0, param2=0},
		{name="air", prob=0, param2=0},
		{name="air", prob=0, param2=0},
		{name="air", prob=0, param2=0},
		{name="air", prob=0, param2=0},
		{name="air", prob=0, param2=0},
		{name="air", prob=0, param2=0},
		{name="air", prob=0, param2=0},
		{name="air", prob=0, param2=0},
		{name="air", prob=0, param2=0},
		{name="air", prob=0, param2=0},
		{name="air", prob=0, param2=0},
		{name="air", prob=0, param2=0},
		{name="air", prob=0, param2=0},
		{name="air", prob=0, param2=0},
		{name="air", prob=0, param2=0},
		{name="air", prob=0, param2=0},
		{name="air", prob=0, param2=0},
		{name="air", prob=0, param2=0},
		{name="air", prob=0, param2=0},
		{name="air", prob=0, param2=0},
		{name="air", prob=0, param2=0},
		{name="air", prob=0, param2=0},
		{name="air", prob=0, param2=0},
		{name="air", prob=0, param2=0},
		{name="air", prob=0, param2=0},
		{name="air", prob=0, param2=0},
		{name="air", prob=0, param2=0},
		{name="air", prob=0, param2=0},
		{name="air", prob=0, param2=0},
		{name="air", prob=0, param2=0},
		{name="air", prob=0, param2=0},
		{name="air", prob=0, param2=0},
		{name="air", prob=0, param2=0},
		{name="air", prob=0, param2=0},
		{name="air", prob=0, param2=0},
		{name="air", prob=0, param2=0},
		{name="air", prob=0, param2=0},
		{name="air", prob=0, param2=0},
		{name="air", prob=0, param2=0},
		{name="air", prob=0, param2=0},
		{name="air", prob=0, param2=0},
		{name="air", prob=0, param2=0},
		{name="air", prob=0, param2=0},
		{name="air", prob=0, param2=0},
		{name="air", prob=0, param2=0},
		{name="air", prob=0, param2=0},
		{name="air", prob=0, param2=0},
		{name="air", prob=0, param2=0},
		{name="air", prob=0, param2=0},
		{name="air", prob=0, param2=0},
		{name="air", prob=0, param2=0},
		{name="air", prob=0, param2=0},
		{name="air", prob=0, param2=0},
		{name="air", prob=0, param2=0},
		{name="air", prob=0, param2=0},
		{name="air", prob=0, param2=0},
		{name="air", prob=0, param2=0},
		{name="mini_nodes:oak_leaves", prob=128, param2=0},
		{name="mini_nodes:apple_leaves", prob=128, param2=0},
		{name="mini_nodes:oak_leaves", prob=128, param2=0},
		{name="air", prob=0, param2=0},
		{name="air", prob=0, param2=0},
		{name="air", prob=0, param2=0},
		{name="air", prob=0, param2=0},
		{name="air", prob=0, param2=0},
		{name="air", prob=0, param2=0},
		{name="air", prob=0, param2=0},
		{name="mini_nodes:oak_leaves", prob=128, param2=0},
		{name="mini_nodes:oak_leaves", prob=254, param2=0},
		{name="mini_nodes:oak_leaves", prob=254, param2=0},
		{name="mini_nodes:oak_leaves", prob=254, param2=0},
		{name="mini_nodes:apple_leaves", prob=254, param2=0},
		{name="mini_nodes:oak_leaves", prob=128, param2=0},
		{name="air", prob=0, param2=0},
		{name="air", prob=0, param2=0},
		{name="air", prob=0, param2=0},
		{name="air", prob=0, param2=0},
		{name="air", prob=0, param2=0},
		{name="mini_nodes:oak_leaves", prob=128, param2=0},
		{name="mini_nodes:oak_leaves", prob=254, param2=0},
		{name="mini_nodes:oak_leaves", prob=254, param2=0},
		{name="mini_nodes:oak_leaves", prob=254, param2=0},
		{name="mini_nodes:oak_leaves", prob=254, param2=0},
		{name="mini_nodes:oak_leaves", prob=254, param2=0},
		{name="air", prob=0, param2=0},
		{name="air", prob=0, param2=0},
		{name="air", prob=0, param2=0},
		{name="air", prob=0, param2=0},
		{name="air", prob=0, param2=0},
		{name="mini_nodes:oak_leaves", prob=128, param2=0},
		{name="mini_nodes:oak_leaves", prob=254, param2=0},
		{name="mini_nodes:oak_leaves", prob=254, param2=0},
		{name="mini_nodes:oak_leaves", prob=254, param2=0},
		{name="mini_nodes:oak_leaves", prob=254, param2=0},
		{name="mini_nodes:oak_leaves", prob=128, param2=0},
		{name="air", prob=0, param2=0},
		{name="air", prob=0, param2=0},
		{name="air", prob=0, param2=0},
		{name="air", prob=0, param2=0},
		{name="air", prob=0, param2=0},
		{name="air", prob=0, param2=0},
		{name="mini_nodes:oak_leaves", prob=128, param2=0},
		{name="mini_nodes:oak_leaves", prob=254, param2=0},
		{name="mini_nodes:oak_leaves", prob=128, param2=0},
		{name="mini_nodes:oak_leaves", prob=254, param2=0},
		{name="air", prob=0, param2=0},
		{name="air", prob=0, param2=0},
		{name="air", prob=0, param2=0},
		{name="air", prob=0, param2=0},
		{name="air", prob=0, param2=0},
		{name="air", prob=0, param2=0},
		{name="air", prob=0, param2=0},
		{name="mini_nodes:oak_leaves", prob=128, param2=0},
		{name="mini_nodes:oak_leaves", prob=254, param2=0},
		{name="air", prob=0, param2=0},
		{name="air", prob=0, param2=0},
		{name="air", prob=0, param2=0},
		{name="air", prob=0, param2=0},
		{name="air", prob=0, param2=0},
		{name="air", prob=0, param2=0},
		{name="air", prob=0, param2=0},
		{name="air", prob=0, param2=0},
		{name="air", prob=0, param2=0},
		{name="air", prob=0, param2=0},
		{name="air", prob=0, param2=0},
		{name="air", prob=0, param2=0},
		{name="air", prob=0, param2=0},
		{name="air", prob=0, param2=0},
		{name="air", prob=0, param2=0},
		{name="air", prob=0, param2=0},
		{name="air", prob=0, param2=0},
		{name="air", prob=0, param2=0},
		{name="air", prob=0, param2=0},
		{name="air", prob=0, param2=0},
		{name="air", prob=0, param2=0},
		{name="air", prob=0, param2=0},
		{name="air", prob=0, param2=0},
		{name="air", prob=0, param2=0},
		{name="air", prob=0, param2=0},
		{name="air", prob=0, param2=0},
		{name="air", prob=0, param2=0},
		{name="air", prob=0, param2=0},
		{name="air", prob=0, param2=0},
		{name="air", prob=0, param2=0},
		{name="air", prob=0, param2=0},
		{name="air", prob=0, param2=0},
		{name="air", prob=0, param2=0},
		{name="air", prob=0, param2=0},
		{name="air", prob=0, param2=0},
		{name="air", prob=0, param2=0},
		{name="air", prob=0, param2=0},
		{name="air", prob=0, param2=0},
		{name="air", prob=0, param2=0},
		{name="air", prob=0, param2=0},
		{name="air", prob=0, param2=0},
		{name="air", prob=0, param2=0},
		{name="air", prob=0, param2=0},
		{name="air", prob=0, param2=0},
		{name="air", prob=0, param2=0},
		{name="air", prob=0, param2=0},
		{name="air", prob=0, param2=0},
		{name="air", prob=0, param2=0},
		{name="air", prob=0, param2=0},
		{name="air", prob=0, param2=0},
		{name="air", prob=0, param2=0},
		{name="air", prob=0, param2=0},
		{name="air", prob=0, param2=0},
		{name="air", prob=0, param2=0},
		{name="air", prob=0, param2=0},
		{name="air", prob=0, param2=0},
		{name="air", prob=0, param2=0},
		{name="air", prob=0, param2=0},
		{name="air", prob=0, param2=0},
		{name="air", prob=0, param2=0},
		{name="air", prob=0, param2=0},
		{name="air", prob=0, param2=0},
		{name="air", prob=0, param2=0},
		{name="air", prob=0, param2=0},
		{name="air", prob=0, param2=0},
		{name="mini_nodes:oak_leaves", prob=128, param2=0},
		{name="mini_nodes:oak_leaves", prob=128, param2=0},
		{name="air", prob=0, param2=0},
		{name="air", prob=0, param2=0},
		{name="air", prob=0, param2=0},
		{name="air", prob=0, param2=0},
		{name="air", prob=0, param2=0},
		{name="air", prob=0, param2=0},
		{name="air", prob=0, param2=0},
		{name="air", prob=0, param2=0},
		{name="mini_nodes:oak_leaves", prob=128, param2=0},
		{name="mini_nodes:oak_leaves", prob=254, param2=0},
		{name="mini_nodes:oak_leaves", prob=254, param2=0},
		{name="mini_nodes:oak_leaves", prob=254, param2=0},
		{name="mini_nodes:oak_leaves", prob=254, param2=0},
		{name="air", prob=0, param2=0},
		{name="air", prob=0, param2=0},
		{name="air", prob=0, param2=0},
		{name="air", prob=0, param2=0},
		{name="air", prob=0, param2=0},
		{name="mini_nodes:oak_leaves", prob=128, param2=0},
		{name="mini_nodes:oak_leaves", prob=254, param2=0},
		{name="mini_nodes:oak_leaves", prob=254, param2=0},
		{name="mini_nodes:oak_tree", prob=254, param2=0},
		{name="mini_nodes:oak_leaves", prob=254, param2=0},
		{name="mini_nodes:oak_leaves", prob=254, param2=0},
		{name="mini_nodes:oak_leaves", prob=128, param2=0},
		{name="air", prob=0, param2=0},
		{name="air", prob=0, param2=0},
		{name="air", prob=0, param2=0},
		{name="mini_nodes:apple_leaves", prob=128, param2=0},
		{name="mini_nodes:oak_leaves", prob=254, param2=0},
		{name="mini_nodes:oak_leaves", prob=254, param2=0},
		{name="mini_nodes:oak_leaves", prob=254, param2=0},
		{name="mini_nodes:oak_leaves", prob=254, param2=0},
		{name="mini_nodes:oak_leaves", prob=254, param2=0},
		{name="mini_nodes:oak_tree", prob=254, param2=0},
		{name="mini_nodes:oak_leaves", prob=254, param2=0},
		{name="air", prob=0, param2=0},
		{name="air", prob=0, param2=0},
		{name="air", prob=0, param2=0},
		{name="mini_nodes:oak_leaves", prob=128, param2=0},
		{name="mini_nodes:oak_leaves", prob=254, param2=0},
		{name="mini_nodes:oak_leaves", prob=254, param2=0},
		{name="mini_nodes:oak_leaves", prob=254, param2=0},
		{name="mini_nodes:oak_leaves", prob=254, param2=0},
		{name="mini_nodes:oak_leaves", prob=254, param2=0},
		{name="mini_nodes:oak_leaves", prob=254, param2=0},
		{name="mini_nodes:oak_leaves", prob=128, param2=0},
		{name="air", prob=0, param2=0},
		{name="air", prob=0, param2=0},
		{name="air", prob=0, param2=0},
		{name="air", prob=0, param2=0},
		{name="mini_nodes:oak_leaves", prob=128, param2=0},
		{name="mini_nodes:oak_leaves", prob=254, param2=0},
		{name="mini_nodes:oak_leaves", prob=254, param2=0},
		{name="mini_nodes:oak_leaves", prob=254, param2=0},
		{name="mini_nodes:oak_leaves", prob=254, param2=0},
		{name="mini_nodes:apple_leaves", prob=128, param2=0},
		{name="air", prob=0, param2=0},
		{name="air", prob=0, param2=0},
		{name="air", prob=0, param2=0},
		{name="air", prob=0, param2=0},
		{name="air", prob=0, param2=0},
		{name="air", prob=0, param2=0},
		{name="mini_nodes:oak_leaves", prob=128, param2=0},
		{name="mini_nodes:oak_leaves", prob=254, param2=0},
		{name="mini_nodes:oak_leaves", prob=128, param2=0},
		{name="mini_nodes:oak_leaves", prob=128, param2=0},
		{name="air", prob=0, param2=0},
		{name="air", prob=0, param2=0},
		{name="air", prob=0, param2=0},
		{name="air", prob=0, param2=0},
		{name="air", prob=0, param2=0},
		{name="air", prob=0, param2=0},
		{name="air", prob=0, param2=0},
		{name="air", prob=0, param2=0},
		{name="mini_nodes:oak_leaves", prob=128, param2=0},
		{name="mini_nodes:oak_leaves", prob=128, param2=0},
		{name="air", prob=0, param2=0},
		{name="air", prob=0, param2=0},
		{name="air", prob=0, param2=0},
		{name="air", prob=0, param2=0},
		{name="air", prob=0, param2=0},
		{name="air", prob=0, param2=0},
		{name="air", prob=0, param2=0},
		{name="air", prob=0, param2=0},
		{name="air", prob=0, param2=0},
		{name="air", prob=0, param2=0},
		{name="air", prob=0, param2=0},
		{name="air", prob=0, param2=0},
		{name="air", prob=0, param2=0},
		{name="air", prob=0, param2=0},
		{name="air", prob=0, param2=0},
		{name="air", prob=0, param2=0},
		{name="air", prob=0, param2=0},
		{name="air", prob=0, param2=0},
		{name="air", prob=0, param2=0},
		{name="air", prob=0, param2=0},
		{name="air", prob=0, param2=0},
		{name="air", prob=0, param2=0},
		{name="air", prob=0, param2=0},
		{name="air", prob=0, param2=0},
		{name="air", prob=0, param2=0},
		{name="air", prob=0, param2=0},
		{name="air", prob=0, param2=0},
		{name="air", prob=0, param2=0},
		{name="air", prob=0, param2=0},
		{name="air", prob=0, param2=0},
		{name="air", prob=0, param2=0},
		{name="air", prob=0, param2=0},
		{name="air", prob=0, param2=0},
		{name="air", prob=0, param2=0},
		{name="air", prob=0, param2=0},
		{name="air", prob=0, param2=0},
		{name="air", prob=0, param2=0},
		{name="air", prob=0, param2=0},
		{name="air", prob=0, param2=0},
		{name="air", prob=0, param2=0},
		{name="air", prob=0, param2=0},
		{name="air", prob=0, param2=0},
		{name="air", prob=0, param2=0},
		{name="air", prob=0, param2=0},
		{name="air", prob=0, param2=0},
		{name="air", prob=0, param2=0},
		{name="air", prob=0, param2=0},
		{name="air", prob=0, param2=0},
		{name="air", prob=0, param2=0},
		{name="air", prob=0, param2=0},
		{name="air", prob=0, param2=0},
		{name="air", prob=0, param2=0},
		{name="air", prob=0, param2=0},
		{name="mini_nodes:oak_leaves", prob=128, param2=0},
		{name="mini_nodes:oak_leaves", prob=128, param2=0},
		{name="mini_nodes:oak_leaves", prob=128, param2=0},
		{name="air", prob=0, param2=0},
		{name="air", prob=0, param2=0},
		{name="air", prob=0, param2=0},
		{name="air", prob=0, param2=0},
		{name="air", prob=0, param2=0},
		{name="air", prob=0, param2=0},
		{name="mini_nodes:apple_leaves", prob=128, param2=0},
		{name="mini_nodes:oak_leaves", prob=254, param2=0},
		{name="mini_nodes:oak_tree", prob=254, param2=0},
		{name="mini_nodes:oak_leaves", prob=254, param2=0},
		{name="mini_nodes:oak_leaves", prob=254, param2=0},
		{name="mini_nodes:oak_leaves", prob=254, param2=0},
		{name="air", prob=0, param2=0},
		{name="air", prob=0, param2=0},
		{name="air", prob=0, param2=0},
		{name="air", prob=0, param2=0},
		{name="mini_nodes:oak_leaves", prob=128, param2=0},
		{name="mini_nodes:oak_leaves", prob=254, param2=0},
		{name="mini_nodes:oak_leaves", prob=254, param2=0},
		{name="mini_nodes:oak_leaves", prob=254, param2=0},
		{name="mini_nodes:oak_leaves", prob=254, param2=0},
		{name="mini_nodes:oak_leaves", prob=254, param2=0},
		{name="mini_nodes:oak_leaves", prob=254, param2=0},
		{name="mini_nodes:oak_leaves", prob=128, param2=0},
		{name="air", prob=0, param2=0},
		{name="air", prob=0, param2=0},
		{name="air", prob=0, param2=0},
		{name="mini_nodes:oak_leaves", prob=128, param2=0},
		{name="mini_nodes:oak_leaves", prob=254, param2=0},
		{name="mini_nodes:oak_leaves", prob=254, param2=0},
		{name="mini_nodes:oak_leaves", prob=254, param2=0},
		{name="mini_nodes:oak_leaves", prob=254, param2=0},
		{name="mini_nodes:oak_leaves", prob=254, param2=0},
		{name="mini_nodes:oak_tree", prob=254, param2=0},
		{name="mini_nodes:oak_leaves", prob=254, param2=0},
		{name="mini_nodes:apple_leaves", prob=128, param2=0},
		{name="air", prob=0, param2=0},
		{name="mini_nodes:oak_leaves", prob=128, param2=0},
		{name="mini_nodes:oak_tree", prob=254, param2=0},
		{name="mini_nodes:oak_leaves", prob=254, param2=0},
		{name="mini_nodes:oak_leaves", prob=254, param2=0},
		{name="mini_nodes:oak_leaves", prob=254, param2=0},
		{name="mini_nodes:oak_tree", prob=254, param2=0},
		{name="mini_nodes:oak_leaves", prob=254, param2=0},
		{name="mini_nodes:oak_leaves", prob=254, param2=0},
		{name="mini_nodes:oak_leaves", prob=254, param2=0},
		{name="mini_nodes:oak_leaves", prob=128, param2=0},
		{name="air", prob=0, param2=0},
		{name="air", prob=0, param2=0},
		{name="mini_nodes:oak_leaves", prob=128, param2=0},
		{name="mini_nodes:oak_leaves", prob=254, param2=0},
		{name="mini_nodes:oak_leaves", prob=254, param2=0},
		{name="mini_nodes:oak_leaves", prob=254, param2=0},
		{name="mini_nodes:oak_leaves", prob=254, param2=0},
		{name="mini_nodes:oak_leaves", prob=254, param2=0},
		{name="mini_nodes:oak_leaves", prob=254, param2=0},
		{name="mini_nodes:oak_leaves", prob=128, param2=0},
		{name="air", prob=0, param2=0},
		{name="air", prob=0, param2=0},
		{name="air", prob=0, param2=0},
		{name="air", prob=0, param2=0},
		{name="mini_nodes:apple_leaves", prob=128, param2=0},
		{name="mini_nodes:oak_leaves", prob=254, param2=0},
		{name="mini_nodes:oak_leaves", prob=254, param2=0},
		{name="mini_nodes:oak_leaves", prob=254, param2=0},
		{name="mini_nodes:oak_leaves", prob=254, param2=0},
		{name="mini_nodes:oak_leaves", prob=128, param2=0},
		{name="air", prob=0, param2=0},
		{name="air", prob=0, param2=0},
		{name="air", prob=0, param2=0},
		{name="air", prob=0, param2=0},
		{name="air", prob=0, param2=0},
		{name="air", prob=0, param2=0},
		{name="mini_nodes:oak_leaves", prob=128, param2=0},
		{name="mini_nodes:oak_leaves", prob=128, param2=0},
		{name="mini_nodes:oak_leaves", prob=128, param2=0},
		{name="mini_nodes:oak_leaves", prob=128, param2=0},
		{name="air", prob=0, param2=0},
		{name="air", prob=0, param2=0},
		{name="air", prob=0, param2=0},
		{name="air", prob=0, param2=0},
		{name="air", prob=0, param2=0},
		{name="air", prob=0, param2=0},
		{name="air", prob=0, param2=0},
		{name="air", prob=0, param2=0},
		{name="air", prob=0, param2=0},
		{name="air", prob=0, param2=0},
		{name="air", prob=0, param2=0},
		{name="air", prob=0, param2=0},
		{name="air", prob=0, param2=0},
		{name="air", prob=0, param2=0},
		{name="air", prob=0, param2=0},
		{name="air", prob=0, param2=0},
		{name="air", prob=0, param2=0},
		{name="air", prob=0, param2=0},
		{name="air", prob=0, param2=0},
		{name="air", prob=0, param2=0},
		{name="air", prob=0, param2=0},
		{name="air", prob=0, param2=0},
		{name="air", prob=0, param2=0},
		{name="air", prob=0, param2=0},
		{name="air", prob=0, param2=0},
		{name="air", prob=0, param2=0},
		{name="air", prob=0, param2=0},
		{name="air", prob=0, param2=0},
		{name="air", prob=0, param2=0},
		{name="air", prob=0, param2=0},
		{name="air", prob=0, param2=0},
		{name="air", prob=0, param2=0},
		{name="air", prob=0, param2=0},
		{name="air", prob=0, param2=0},
		{name="air", prob=0, param2=0},
		{name="air", prob=0, param2=0},
		{name="air", prob=0, param2=0},
		{name="air", prob=0, param2=0},
		{name="air", prob=0, param2=0},
		{name="air", prob=0, param2=0},
		{name="air", prob=0, param2=0},
		{name="air", prob=0, param2=0},
		{name="air", prob=0, param2=0},
		{name="air", prob=0, param2=0},
		{name="air", prob=0, param2=0},
		{name="air", prob=0, param2=0},
		{name="air", prob=0, param2=0},
		{name="air", prob=0, param2=0},
		{name="air", prob=0, param2=0},
		{name="air", prob=0, param2=0},
		{name="air", prob=0, param2=0},
		{name="mini_nodes:oak_leaves", prob=128, param2=0},
		{name="mini_nodes:oak_leaves", prob=128, param2=0},
		{name="mini_nodes:oak_tree", prob=254, param2=0},
		{name="mini_nodes:oak_leaves", prob=128, param2=0},
		{name="mini_nodes:oak_leaves", prob=128, param2=0},
		{name="air", prob=0, param2=0},
		{name="air", prob=0, param2=0},
		{name="air", prob=0, param2=0},
		{name="air", prob=0, param2=0},
		{name="air", prob=0, param2=0},
		{name="mini_nodes:oak_leaves", prob=128, param2=0},
		{name="mini_nodes:oak_leaves", prob=254, param2=0},
		{name="mini_nodes:oak_leaves", prob=254, param2=0},
		{name="mini_nodes:oak_leaves", prob=254, param2=0},
		{name="mini_nodes:oak_leaves", prob=254, param2=0},
		{name="mini_nodes:oak_leaves", prob=254, param2=0},
		{name="mini_nodes:oak_leaves", prob=128, param2=0},
		{name="air", prob=0, param2=0},
		{name="air", prob=0, param2=0},
		{name="air", prob=0, param2=0},
		{name="mini_nodes:oak_leaves", prob=128, param2=0},
		{name="mini_nodes:oak_leaves", prob=254, param2=0},
		{name="mini_nodes:oak_leaves", prob=254, param2=0},
		{name="mini_nodes:oak_leaves", prob=254, param2=0},
		{name="mini_nodes:oak_leaves", prob=254, param2=0},
		{name="mini_nodes:oak_tree", prob=254, param2=0},
		{name="mini_nodes:oak_leaves", prob=254, param2=0},
		{name="mini_nodes:oak_leaves", prob=254, param2=0},
		{name="mini_nodes:oak_leaves", prob=128, param2=0},
		{name="air", prob=0, param2=0},
		{name="mini_nodes:oak_leaves", prob=128, param2=0},
		{name="mini_nodes:oak_leaves", prob=254, param2=0},
		{name="mini_nodes:oak_tree", prob=254, param2=0},
		{name="mini_nodes:oak_leaves", prob=254, param2=0},
		{name="mini_nodes:oak_tree", prob=254, param2=0},
		{name="mini_nodes:oak_leaves", prob=254, param2=0},
		{name="mini_nodes:oak_leaves", prob=254, param2=0},
		{name="mini_nodes:oak_leaves", prob=254, param2=0},
		{name="mini_nodes:oak_leaves", prob=254, param2=0},
		{name="mini_nodes:oak_leaves", prob=254, param2=0},
		{name="air", prob=0, param2=0},
		{name="mini_nodes:oak_leaves", prob=128, param2=0},
		{name="mini_nodes:oak_leaves", prob=254, param2=0},
		{name="mini_nodes:oak_leaves", prob=254, param2=0},
		{name="mini_nodes:oak_leaves", prob=254, param2=0},
		{name="mini_nodes:oak_leaves", prob=254, param2=0},
		{name="mini_nodes:oak_leaves", prob=254, param2=0},
		{name="mini_nodes:oak_leaves", prob=254, param2=0},
		{name="mini_nodes:oak_leaves", prob=254, param2=0},
		{name="mini_nodes:oak_leaves", prob=254, param2=0},
		{name="mini_nodes:oak_leaves", prob=254, param2=0},
		{name="mini_nodes:oak_leaves", prob=128, param2=0},
		{name="mini_nodes:apple_leaves", prob=128, param2=0},
		{name="mini_nodes:oak_leaves", prob=128, param2=0},
		{name="mini_nodes:oak_leaves", prob=254, param2=0},
		{name="mini_nodes:oak_leaves", prob=254, param2=0},
		{name="mini_nodes:oak_leaves", prob=254, param2=0},
		{name="mini_nodes:oak_leaves", prob=254, param2=0},
		{name="mini_nodes:oak_tree", prob=254, param2=0},
		{name="mini_nodes:oak_leaves", prob=254, param2=0},
		{name="mini_nodes:oak_leaves", prob=128, param2=0},
		{name="mini_nodes:oak_leaves", prob=128, param2=0},
		{name="air", prob=0, param2=0},
		{name="air", prob=0, param2=0},
		{name="air", prob=0, param2=0},
		{name="mini_nodes:oak_leaves", prob=128, param2=0},
		{name="mini_nodes:oak_leaves", prob=254, param2=0},
		{name="mini_nodes:oak_leaves", prob=254, param2=0},
		{name="mini_nodes:oak_leaves", prob=254, param2=0},
		{name="mini_nodes:oak_leaves", prob=254, param2=0},
		{name="mini_nodes:oak_leaves", prob=254, param2=0},
		{name="air", prob=0, param2=0},
		{name="air", prob=0, param2=0},
		{name="air", prob=0, param2=0},
		{name="air", prob=0, param2=0},
		{name="air", prob=0, param2=0},
		{name="mini_nodes:oak_leaves", prob=128, param2=0},
		{name="mini_nodes:oak_leaves", prob=128, param2=0},
		{name="mini_nodes:oak_leaves", prob=128, param2=0},
		{name="mini_nodes:oak_leaves", prob=128, param2=0},
		{name="mini_nodes:apple_leaves", prob=128, param2=0},
		{name="mini_nodes:oak_leaves", prob=128, param2=0},
		{name="air", prob=0, param2=0},
		{name="air", prob=0, param2=0},
		{name="air", prob=0, param2=0},
		{name="air", prob=0, param2=0},
		{name="air", prob=0, param2=0},
		{name="air", prob=0, param2=0},
		{name="air", prob=0, param2=0},
		{name="air", prob=0, param2=0},
		{name="mini_nodes:dirt", prob=254, param2=0},
		{name="air", prob=0, param2=0},
		{name="air", prob=0, param2=0},
		{name="air", prob=0, param2=0},
		{name="air", prob=0, param2=0},
		{name="air", prob=0, param2=0},
		{name="air", prob=0, param2=0},
		{name="air", prob=0, param2=0},
		{name="air", prob=0, param2=0},
		{name="air", prob=0, param2=0},
		{name="air", prob=0, param2=0},
		{name="mini_nodes:oak_tree", prob=254, param2=0},
		{name="air", prob=0, param2=0},
		{name="air", prob=0, param2=0},
		{name="air", prob=0, param2=0},
		{name="air", prob=0, param2=0},
		{name="air", prob=0, param2=0},
		{name="air", prob=0, param2=0},
		{name="air", prob=0, param2=0},
		{name="air", prob=0, param2=0},
		{name="air", prob=0, param2=0},
		{name="air", prob=0, param2=0},
		{name="mini_nodes:oak_tree", prob=254, param2=0},
		{name="air", prob=0, param2=0},
		{name="air", prob=0, param2=0},
		{name="air", prob=0, param2=0},
		{name="air", prob=0, param2=0},
		{name="air", prob=0, param2=0},
		{name="air", prob=0, param2=0},
		{name="air", prob=0, param2=0},
		{name="air", prob=0, param2=0},
		{name="air", prob=0, param2=0},
		{name="air", prob=0, param2=0},
		{name="mini_nodes:oak_tree", prob=254, param2=0},
		{name="air", prob=0, param2=0},
		{name="air", prob=0, param2=0},
		{name="air", prob=0, param2=0},
		{name="air", prob=0, param2=0},
		{name="air", prob=0, param2=0},
		{name="air", prob=0, param2=0},
		{name="air", prob=0, param2=0},
		{name="air", prob=0, param2=0},
		{name="mini_nodes:oak_leaves", prob=128, param2=0},
		{name="mini_nodes:oak_leaves", prob=128, param2=0},
		{name="mini_nodes:oak_tree", prob=254, param2=0},
		{name="mini_nodes:oak_leaves", prob=128, param2=0},
		{name="mini_nodes:oak_leaves", prob=128, param2=0},
		{name="air", prob=0, param2=0},
		{name="air", prob=0, param2=0},
		{name="air", prob=0, param2=0},
		{name="air", prob=0, param2=0},
		{name="air", prob=0, param2=0},
		{name="mini_nodes:oak_leaves", prob=128, param2=0},
		{name="mini_nodes:oak_leaves", prob=254, param2=0},
		{name="mini_nodes:oak_tree", prob=254, param2=0},
		{name="mini_nodes:oak_tree", prob=254, param2=0},
		{name="mini_nodes:oak_leaves", prob=254, param2=0},
		{name="mini_nodes:oak_leaves", prob=254, param2=0},
		{name="mini_nodes:oak_leaves", prob=128, param2=0},
		{name="mini_nodes:oak_leaves", prob=128, param2=0},
		{name="air", prob=0, param2=0},
		{name="air", prob=0, param2=0},
		{name="mini_nodes:oak_leaves", prob=128, param2=0},
		{name="mini_nodes:oak_leaves", prob=254, param2=0},
		{name="mini_nodes:oak_tree", prob=254, param2=0},
		{name="mini_nodes:oak_leaves", prob=254, param2=0},
		{name="mini_nodes:oak_leaves", prob=254, param2=0},
		{name="mini_nodes:oak_leaves", prob=254, param2=0},
		{name="mini_nodes:oak_leaves", prob=254, param2=0},
		{name="mini_nodes:oak_leaves", prob=254, param2=0},
		{name="mini_nodes:oak_leaves", prob=254, param2=0},
		{name="air", prob=0, param2=0},
		{name="mini_nodes:oak_leaves", prob=128, param2=0},
		{name="mini_nodes:oak_leaves", prob=254, param2=0},
		{name="mini_nodes:oak_leaves", prob=254, param2=0},
		{name="mini_nodes:oak_leaves", prob=254, param2=0},
		{name="mini_nodes:oak_leaves", prob=254, param2=0},
		{name="mini_nodes:oak_leaves", prob=254, param2=0},
		{name="mini_nodes:oak_leaves", prob=254, param2=0},
		{name="mini_nodes:oak_tree", prob=254, param2=0},
		{name="mini_nodes:oak_leaves", prob=254, param2=0},
		{name="mini_nodes:oak_leaves", prob=254, param2=0},
		{name="mini_nodes:oak_leaves", prob=128, param2=0},
		{name="mini_nodes:oak_leaves", prob=128, param2=0},
		{name="mini_nodes:oak_leaves", prob=254, param2=0},
		{name="mini_nodes:oak_leaves", prob=254, param2=0},
		{name="mini_nodes:oak_leaves", prob=254, param2=0},
		{name="mini_nodes:oak_leaves", prob=254, param2=0},
		{name="mini_nodes:oak_leaves", prob=254, param2=0},
		{name="mini_nodes:oak_leaves", prob=254, param2=0},
		{name="mini_nodes:oak_leaves", prob=254, param2=0},
		{name="mini_nodes:oak_leaves", prob=254, param2=0},
		{name="mini_nodes:oak_leaves", prob=254, param2=0},
		{name="mini_nodes:oak_leaves", prob=128, param2=0},
		{name="mini_nodes:oak_leaves", prob=128, param2=0},
		{name="mini_nodes:oak_leaves", prob=254, param2=0},
		{name="mini_nodes:oak_leaves", prob=254, param2=0},
		{name="mini_nodes:oak_leaves", prob=254, param2=0},
		{name="mini_nodes:oak_leaves", prob=254, param2=0},
		{name="mini_nodes:oak_leaves", prob=254, param2=0},
		{name="mini_nodes:oak_leaves", prob=254, param2=0},
		{name="mini_nodes:oak_leaves", prob=254, param2=0},
		{name="mini_nodes:oak_leaves", prob=254, param2=0},
		{name="mini_nodes:apple_leaves", prob=128, param2=0},
		{name="air", prob=0, param2=0},
		{name="air", prob=0, param2=0},
		{name="mini_nodes:oak_leaves", prob=128, param2=0},
		{name="mini_nodes:oak_leaves", prob=254, param2=0},
		{name="mini_nodes:oak_leaves", prob=254, param2=0},
		{name="mini_nodes:oak_leaves", prob=254, param2=0},
		{name="mini_nodes:oak_leaves", prob=254, param2=0},
		{name="mini_nodes:oak_leaves", prob=254, param2=0},
		{name="mini_nodes:oak_leaves", prob=254, param2=0},
		{name="mini_nodes:oak_leaves", prob=128, param2=0},
		{name="air", prob=0, param2=0},
		{name="air", prob=0, param2=0},
		{name="air", prob=0, param2=0},
		{name="air", prob=0, param2=0},
		{name="mini_nodes:oak_leaves", prob=128, param2=0},
		{name="mini_nodes:apple_leaves", prob=128, param2=0},
		{name="mini_nodes:oak_leaves", prob=128, param2=0},
		{name="mini_nodes:oak_leaves", prob=128, param2=0},
		{name="mini_nodes:oak_leaves", prob=128, param2=0},
		{name="mini_nodes:oak_leaves", prob=128, param2=0},
		{name="air", prob=0, param2=0},
		{name="air", prob=0, param2=0},
		{name="air", prob=0, param2=0},
		{name="air", prob=0, param2=0},
		{name="air", prob=0, param2=0},
		{name="air", prob=0, param2=0},
		{name="air", prob=0, param2=0},
		{name="air", prob=0, param2=0},
		{name="air", prob=0, param2=0},
		{name="air", prob=0, param2=0},
		{name="air", prob=0, param2=0},
		{name="air", prob=0, param2=0},
		{name="air", prob=0, param2=0},
		{name="air", prob=0, param2=0},
		{name="air", prob=0, param2=0},
		{name="air", prob=0, param2=0},
		{name="air", prob=0, param2=0},
		{name="air", prob=0, param2=0},
		{name="air", prob=0, param2=0},
		{name="air", prob=0, param2=0},
		{name="air", prob=0, param2=0},
		{name="air", prob=0, param2=0},
		{name="air", prob=0, param2=0},
		{name="air", prob=0, param2=0},
		{name="air", prob=0, param2=0},
		{name="air", prob=0, param2=0},
		{name="air", prob=0, param2=0},
		{name="air", prob=0, param2=0},
		{name="air", prob=0, param2=0},
		{name="air", prob=0, param2=0},
		{name="air", prob=0, param2=0},
		{name="air", prob=0, param2=0},
		{name="air", prob=0, param2=0},
		{name="air", prob=0, param2=0},
		{name="air", prob=0, param2=0},
		{name="air", prob=0, param2=0},
		{name="air", prob=0, param2=0},
		{name="air", prob=0, param2=0},
		{name="air", prob=0, param2=0},
		{name="air", prob=0, param2=0},
		{name="air", prob=0, param2=0},
		{name="air", prob=0, param2=0},
		{name="air", prob=0, param2=0},
		{name="air", prob=0, param2=0},
		{name="air", prob=0, param2=0},
		{name="air", prob=0, param2=0},
		{name="air", prob=0, param2=0},
		{name="air", prob=0, param2=0},
		{name="air", prob=0, param2=0},
		{name="air", prob=0, param2=0},
		{name="mini_nodes:oak_leaves", prob=128, param2=0},
		{name="mini_nodes:oak_leaves", prob=128, param2=0},
		{name="mini_nodes:oak_leaves", prob=128, param2=0},
		{name="mini_nodes:oak_leaves", prob=128, param2=0},
		{name="mini_nodes:oak_leaves", prob=128, param2=0},
		{name="air", prob=0, param2=0},
		{name="air", prob=0, param2=0},
		{name="air", prob=0, param2=0},
		{name="air", prob=0, param2=0},
		{name="air", prob=0, param2=0},
		{name="mini_nodes:oak_leaves", prob=128, param2=0},
		{name="mini_nodes:oak_leaves", prob=128, param2=0},
		{name="mini_nodes:oak_leaves", prob=254, param2=0},
		{name="mini_nodes:oak_leaves", prob=254, param2=0},
		{name="mini_nodes:oak_leaves", prob=254, param2=0},
		{name="mini_nodes:oak_leaves", prob=254, param2=0},
		{name="mini_nodes:oak_leaves", prob=128, param2=0},
		{name="mini_nodes:apple_leaves", prob=128, param2=0},
		{name="air", prob=0, param2=0},
		{name="air", prob=0, param2=0},
		{name="air", prob=0, param2=0},
		{name="mini_nodes:oak_leaves", prob=128, param2=0},
		{name="mini_nodes:oak_leaves", prob=254, param2=0},
		{name="mini_nodes:oak_leaves", prob=254, param2=0},
		{name="mini_nodes:oak_tree", prob=254, param2=0},
		{name="mini_nodes:oak_leaves", prob=254, param2=0},
		{name="mini_nodes:oak_leaves", prob=254, param2=0},
		{name="mini_nodes:oak_leaves", prob=254, param2=0},
		{name="mini_nodes:oak_leaves", prob=254, param2=0},
		{name="air", prob=0, param2=0},
		{name="mini_nodes:apple_leaves", prob=128, param2=0},
		{name="mini_nodes:oak_leaves", prob=128, param2=0},
		{name="mini_nodes:oak_tree", prob=254, param2=0},
		{name="mini_nodes:oak_leaves", prob=254, param2=0},
		{name="mini_nodes:oak_leaves", prob=254, param2=0},
		{name="mini_nodes:oak_leaves", prob=254, param2=0},
		{name="mini_nodes:oak_leaves", prob=254, param2=0},
		{name="mini_nodes:oak_leaves", prob=254, param2=0},
		{name="mini_nodes:oak_leaves", prob=254, param2=0},
		{name="mini_nodes:oak_leaves", prob=254, param2=0},
		{name="mini_nodes:apple_leaves", prob=128, param2=0},
		{name="mini_nodes:oak_leaves", prob=128, param2=0},
		{name="mini_nodes:oak_leaves", prob=254, param2=0},
		{name="mini_nodes:oak_leaves", prob=254, param2=0},
		{name="mini_nodes:oak_leaves", prob=254, param2=0},
		{name="mini_nodes:oak_leaves", prob=254, param2=0},
		{name="mini_nodes:oak_leaves", prob=254, param2=0},
		{name="mini_nodes:oak_leaves", prob=254, param2=0},
		{name="mini_nodes:oak_leaves", prob=254, param2=0},
		{name="mini_nodes:oak_tree", prob=254, param2=0},
		{name="mini_nodes:oak_leaves", prob=128, param2=0},
		{name="mini_nodes:oak_leaves", prob=128, param2=0},
		{name="mini_nodes:oak_leaves", prob=128, param2=0},
		{name="mini_nodes:oak_leaves", prob=254, param2=0},
		{name="mini_nodes:oak_leaves", prob=254, param2=0},
		{name="mini_nodes:oak_tree", prob=254, param2=0},
		{name="mini_nodes:oak_leaves", prob=254, param2=0},
		{name="mini_nodes:oak_leaves", prob=254, param2=0},
		{name="mini_nodes:oak_leaves", prob=254, param2=0},
		{name="mini_nodes:oak_leaves", prob=254, param2=0},
		{name="mini_nodes:oak_leaves", prob=128, param2=0},
		{name="air", prob=0, param2=0},
		{name="air", prob=0, param2=0},
		{name="air", prob=0, param2=0},
		{name="mini_nodes:oak_leaves", prob=128, param2=0},
		{name="mini_nodes:oak_leaves", prob=128, param2=0},
		{name="mini_nodes:oak_leaves", prob=254, param2=0},
		{name="mini_nodes:oak_leaves", prob=254, param2=0},
		{name="mini_nodes:oak_leaves", prob=254, param2=0},
		{name="mini_nodes:oak_leaves", prob=254, param2=0},
		{name="mini_nodes:oak_leaves", prob=128, param2=0},
		{name="air", prob=0, param2=0},
		{name="air", prob=0, param2=0},
		{name="air", prob=0, param2=0},
		{name="air", prob=0, param2=0},
		{name="air", prob=0, param2=0},
		{name="air", prob=0, param2=0},
		{name="mini_nodes:oak_leaves", prob=128, param2=0},
		{name="mini_nodes:oak_leaves", prob=128, param2=0},
		{name="mini_nodes:oak_leaves", prob=128, param2=0},
		{name="mini_nodes:oak_leaves", prob=128, param2=0},
		{name="air", prob=0, param2=0},
		{name="air", prob=0, param2=0},
		{name="air", prob=0, param2=0},
		{name="air", prob=0, param2=0},
		{name="air", prob=0, param2=0},
		{name="air", prob=0, param2=0},
		{name="air", prob=0, param2=0},
		{name="air", prob=0, param2=0},
		{name="air", prob=0, param2=0},
		{name="air", prob=0, param2=0},
		{name="air", prob=0, param2=0},
		{name="air", prob=0, param2=0},
		{name="air", prob=0, param2=0},
		{name="air", prob=0, param2=0},
		{name="air", prob=0, param2=0},
		{name="air", prob=0, param2=0},
		{name="air", prob=0, param2=0},
		{name="air", prob=0, param2=0},
		{name="air", prob=0, param2=0},
		{name="air", prob=0, param2=0},
		{name="air", prob=0, param2=0},
		{name="air", prob=0, param2=0},
		{name="air", prob=0, param2=0},
		{name="air", prob=0, param2=0},
		{name="air", prob=0, param2=0},
		{name="air", prob=0, param2=0},
		{name="air", prob=0, param2=0},
		{name="air", prob=0, param2=0},
		{name="air", prob=0, param2=0},
		{name="air", prob=0, param2=0},
		{name="air", prob=0, param2=0},
		{name="air", prob=0, param2=0},
		{name="air", prob=0, param2=0},
		{name="air", prob=0, param2=0},
		{name="air", prob=0, param2=0},
		{name="air", prob=0, param2=0},
		{name="air", prob=0, param2=0},
		{name="air", prob=0, param2=0},
		{name="air", prob=0, param2=0},
		{name="air", prob=0, param2=0},
		{name="air", prob=0, param2=0},
		{name="air", prob=0, param2=0},
		{name="air", prob=0, param2=0},
		{name="air", prob=0, param2=0},
		{name="air", prob=0, param2=0},
		{name="air", prob=0, param2=0},
		{name="air", prob=0, param2=0},
		{name="air", prob=0, param2=0},
		{name="air", prob=0, param2=0},
		{name="air", prob=0, param2=0},
		{name="air", prob=0, param2=0},
		{name="air", prob=0, param2=0},
		{name="air", prob=0, param2=0},
		{name="mini_nodes:apple_leaves", prob=128, param2=0},
		{name="mini_nodes:oak_leaves", prob=128, param2=0},
		{name="air", prob=0, param2=0},
		{name="air", prob=0, param2=0},
		{name="air", prob=0, param2=0},
		{name="air", prob=0, param2=0},
		{name="air", prob=0, param2=0},
		{name="air", prob=0, param2=0},
		{name="air", prob=0, param2=0},
		{name="air", prob=0, param2=0},
		{name="mini_nodes:oak_leaves", prob=128, param2=0},
		{name="mini_nodes:oak_leaves", prob=254, param2=0},
		{name="mini_nodes:oak_leaves", prob=254, param2=0},
		{name="mini_nodes:oak_leaves", prob=128, param2=0},
		{name="mini_nodes:oak_leaves", prob=128, param2=0},
		{name="air", prob=0, param2=0},
		{name="air", prob=0, param2=0},
		{name="air", prob=0, param2=0},
		{name="air", prob=0, param2=0},
		{name="mini_nodes:apple_leaves", prob=128, param2=0},
		{name="mini_nodes:oak_leaves", prob=254, param2=0},
		{name="mini_nodes:oak_leaves", prob=254, param2=0},
		{name="mini_nodes:oak_tree", prob=254, param2=0},
		{name="mini_nodes:oak_leaves", prob=254, param2=0},
		{name="mini_nodes:oak_leaves", prob=254, param2=0},
		{name="mini_nodes:oak_leaves", prob=128, param2=0},
		{name="mini_nodes:oak_leaves", prob=128, param2=0},
		{name="air", prob=0, param2=0},
		{name="air", prob=0, param2=0},
		{name="mini_nodes:oak_leaves", prob=128, param2=0},
		{name="mini_nodes:oak_leaves", prob=254, param2=0},
		{name="mini_nodes:oak_leaves", prob=254, param2=0},
		{name="mini_nodes:oak_tree", prob=254, param2=0},
		{name="mini_nodes:oak_leaves", prob=254, param2=0},
		{name="mini_nodes:oak_leaves", prob=254, param2=0},
		{name="mini_nodes:oak_leaves", prob=254, param2=0},
		{name="mini_nodes:oak_leaves", prob=254, param2=0},
		{name="mini_nodes:oak_leaves", prob=128, param2=0},
		{name="air", prob=0, param2=0},
		{name="mini_nodes:oak_leaves", prob=128, param2=0},
		{name="mini_nodes:oak_leaves", prob=254, param2=0},
		{name="mini_nodes:oak_tree", prob=254, param2=0},
		{name="mini_nodes:oak_leaves", prob=254, param2=0},
		{name="mini_nodes:oak_leaves", prob=254, param2=0},
		{name="mini_nodes:oak_leaves", prob=254, param2=0},
		{name="mini_nodes:oak_tree", prob=254, param2=0},
		{name="mini_nodes:oak_leaves", prob=254, param2=0},
		{name="mini_nodes:oak_leaves", prob=254, param2=0},
		{name="mini_nodes:oak_leaves", prob=128, param2=0},
		{name="air", prob=0, param2=0},
		{name="air", prob=0, param2=0},
		{name="mini_nodes:oak_leaves", prob=128, param2=0},
		{name="mini_nodes:oak_leaves", prob=128, param2=0},
		{name="mini_nodes:oak_leaves", prob=254, param2=0},
		{name="mini_nodes:oak_leaves", prob=254, param2=0},
		{name="mini_nodes:oak_leaves", prob=254, param2=0},
		{name="mini_nodes:oak_leaves", prob=254, param2=0},
		{name="mini_nodes:oak_leaves", prob=254, param2=0},
		{name="mini_nodes:oak_leaves", prob=128, param2=0},
		{name="air", prob=0, param2=0},
		{name="air", prob=0, param2=0},
		{name="air", prob=0, param2=0},
		{name="air", prob=0, param2=0},
		{name="mini_nodes:apple_leaves", prob=128, param2=0},
		{name="mini_nodes:oak_leaves", prob=128, param2=0},
		{name="mini_nodes:oak_leaves", prob=254, param2=0},
		{name="mini_nodes:oak_leaves", prob=128, param2=0},
		{name="mini_nodes:apple_leaves", prob=128, param2=0},
		{name="air", prob=0, param2=0},
		{name="air", prob=0, param2=0},
		{name="air", prob=0, param2=0},
		{name="air", prob=0, param2=0},
		{name="air", prob=0, param2=0},
		{name="air", prob=0, param2=0},
		{name="air", prob=0, param2=0},
		{name="air", prob=0, param2=0},
		{name="mini_nodes:oak_leaves", prob=128, param2=0},
		{name="air", prob=0, param2=0},
		{name="air", prob=0, param2=0},
		{name="air", prob=0, param2=0},
		{name="air", prob=0, param2=0},
		{name="air", prob=0, param2=0},
		{name="air", prob=0, param2=0},
		{name="air", prob=0, param2=0},
		{name="air", prob=0, param2=0},
		{name="air", prob=0, param2=0},
		{name="air", prob=0, param2=0},
		{name="air", prob=0, param2=0},
		{name="air", prob=0, param2=0},
		{name="air", prob=0, param2=0},
		{name="air", prob=0, param2=0},
		{name="air", prob=0, param2=0},
		{name="air", prob=0, param2=0},
		{name="air", prob=0, param2=0},
		{name="air", prob=0, param2=0},
		{name="air", prob=0, param2=0},
		{name="air", prob=0, param2=0},
		{name="air", prob=0, param2=0},
		{name="air", prob=0, param2=0},
		{name="air", prob=0, param2=0},
		{name="air", prob=0, param2=0},
		{name="air", prob=0, param2=0},
		{name="air", prob=0, param2=0},
		{name="air", prob=0, param2=0},
		{name="air", prob=0, param2=0},
		{name="air", prob=0, param2=0},
		{name="air", prob=0, param2=0},
		{name="air", prob=0, param2=0},
		{name="air", prob=0, param2=0},
		{name="air", prob=0, param2=0},
		{name="air", prob=0, param2=0},
		{name="air", prob=0, param2=0},
		{name="air", prob=0, param2=0},
		{name="air", prob=0, param2=0},
		{name="air", prob=0, param2=0},
		{name="air", prob=0, param2=0},
		{name="air", prob=0, param2=0},
		{name="air", prob=0, param2=0},
		{name="air", prob=0, param2=0},
		{name="air", prob=0, param2=0},
		{name="air", prob=0, param2=0},
		{name="air", prob=0, param2=0},
		{name="air", prob=0, param2=0},
		{name="air", prob=0, param2=0},
		{name="air", prob=0, param2=0},
		{name="air", prob=0, param2=0},
		{name="air", prob=0, param2=0},
		{name="air", prob=0, param2=0},
		{name="air", prob=0, param2=0},
		{name="air", prob=0, param2=0},
		{name="air", prob=0, param2=0},
		{name="air", prob=0, param2=0},
		{name="air", prob=0, param2=0},
		{name="air", prob=0, param2=0},
		{name="air", prob=0, param2=0},
		{name="air", prob=0, param2=0},
		{name="air", prob=0, param2=0},
		{name="air", prob=0, param2=0},
		{name="air", prob=0, param2=0},
		{name="air", prob=0, param2=0},
		{name="air", prob=0, param2=0},
		{name="air", prob=0, param2=0},
		{name="air", prob=0, param2=0},
		{name="mini_nodes:oak_leaves", prob=128, param2=0},
		{name="mini_nodes:oak_leaves", prob=128, param2=0},
		{name="mini_nodes:oak_leaves", prob=128, param2=0},
		{name="air", prob=0, param2=0},
		{name="air", prob=0, param2=0},
		{name="air", prob=0, param2=0},
		{name="air", prob=0, param2=0},
		{name="air", prob=0, param2=0},
		{name="air", prob=0, param2=0},
		{name="mini_nodes:oak_leaves", prob=128, param2=0},
		{name="mini_nodes:oak_leaves", prob=128, param2=0},
		{name="mini_nodes:oak_leaves", prob=254, param2=0},
		{name="mini_nodes:oak_leaves", prob=254, param2=0},
		{name="mini_nodes:apple_leaves", prob=128, param2=0},
		{name="air", prob=0, param2=0},
		{name="air", prob=0, param2=0},
		{name="air", prob=0, param2=0},
		{name="air", prob=0, param2=0},
		{name="air", prob=0, param2=0},
		{name="mini_nodes:oak_leaves", prob=128, param2=0},
		{name="mini_nodes:oak_leaves", prob=254, param2=0},
		{name="mini_nodes:oak_leaves", prob=254, param2=0},
		{name="mini_nodes:oak_leaves", prob=254, param2=0},
		{name="mini_nodes:oak_tree", prob=254, param2=0},
		{name="mini_nodes:oak_tree", prob=254, param2=0},
		{name="mini_nodes:oak_leaves", prob=128, param2=0},
		{name="air", prob=0, param2=0},
		{name="air", prob=0, param2=0},
		{name="air", prob=0, param2=0},
		{name="mini_nodes:oak_leaves", prob=128, param2=0},
		{name="mini_nodes:oak_leaves", prob=128, param2=0},
		{name="mini_nodes:oak_leaves", prob=254, param2=0},
		{name="mini_nodes:oak_leaves", prob=254, param2=0},
		{name="mini_nodes:oak_leaves", prob=254, param2=0},
		{name="mini_nodes:oak_leaves", prob=254, param2=0},
		{name="mini_nodes:oak_leaves", prob=254, param2=0},
		{name="mini_nodes:oak_leaves", prob=128, param2=0},
		{name="air", prob=0, param2=0},
		{name="air", prob=0, param2=0},
		{name="air", prob=0, param2=0},
		{name="air", prob=0, param2=0},
		{name="air", prob=0, param2=0},
		{name="mini_nodes:oak_leaves", prob=128, param2=0},
		{name="mini_nodes:oak_leaves", prob=254, param2=0},
		{name="mini_nodes:oak_leaves", prob=254, param2=0},
		{name="mini_nodes:oak_leaves", prob=254, param2=0},
		{name="mini_nodes:oak_leaves", prob=128, param2=0},
		{name="air", prob=0, param2=0},
		{name="air", prob=0, param2=0},
		{name="air", prob=0, param2=0},
		{name="air", prob=0, param2=0},
		{name="air", prob=0, param2=0},
		{name="air", prob=0, param2=0},
		{name="air", prob=0, param2=0},
		{name="mini_nodes:oak_leaves", prob=128, param2=0},
		{name="air", prob=0, param2=0},
		{name="air", prob=0, param2=0},
		{name="air", prob=0, param2=0},
		{name="air", prob=0, param2=0},
		{name="air", prob=0, param2=0},
		{name="air", prob=0, param2=0},
		{name="air", prob=0, param2=0},
		{name="air", prob=0, param2=0},
		{name="air", prob=0, param2=0},
		{name="air", prob=0, param2=0},
		{name="air", prob=0, param2=0},
		{name="air", prob=0, param2=0},
		{name="air", prob=0, param2=0},
		{name="air", prob=0, param2=0},
		{name="air", prob=0, param2=0},
		{name="air", prob=0, param2=0},
		{name="air", prob=0, param2=0},
		{name="air", prob=0, param2=0},
		{name="air", prob=0, param2=0},
		{name="air", prob=0, param2=0},
		{name="air", prob=0, param2=0},
		{name="air", prob=0, param2=0},
		{name="air", prob=0, param2=0},
		{name="air", prob=0, param2=0},
		{name="air", prob=0, param2=0},
		{name="air", prob=0, param2=0},
		{name="air", prob=0, param2=0},
		{name="air", prob=0, param2=0},
		{name="air", prob=0, param2=0},
		{name="air", prob=0, param2=0},
		{name="air", prob=0, param2=0},
		{name="air", prob=0, param2=0},
		{name="air", prob=0, param2=0},
		{name="air", prob=0, param2=0},
		{name="air", prob=0, param2=0},
		{name="air", prob=0, param2=0},
		{name="air", prob=0, param2=0},
		{name="air", prob=0, param2=0},
		{name="air", prob=0, param2=0},
		{name="air", prob=0, param2=0},
		{name="air", prob=0, param2=0},
		{name="air", prob=0, param2=0},
		{name="air", prob=0, param2=0},
		{name="air", prob=0, param2=0},
		{name="air", prob=0, param2=0},
		{name="air", prob=0, param2=0},
		{name="air", prob=0, param2=0},
		{name="air", prob=0, param2=0},
		{name="air", prob=0, param2=0},
		{name="air", prob=0, param2=0},
		{name="air", prob=0, param2=0},
		{name="air", prob=0, param2=0},
		{name="air", prob=0, param2=0},
		{name="air", prob=0, param2=0},
		{name="air", prob=0, param2=0},
		{name="air", prob=0, param2=0},
		{name="air", prob=0, param2=0},
		{name="air", prob=0, param2=0},
		{name="air", prob=0, param2=0},
		{name="air", prob=0, param2=0},
		{name="air", prob=0, param2=0},
		{name="air", prob=0, param2=0},
		{name="air", prob=0, param2=0},
		{name="air", prob=0, param2=0},
		{name="air", prob=0, param2=0},
		{name="air", prob=0, param2=0},
		{name="air", prob=0, param2=0},
		{name="air", prob=0, param2=0},
		{name="air", prob=0, param2=0},
		{name="air", prob=0, param2=0},
		{name="air", prob=0, param2=0},
		{name="air", prob=0, param2=0},
		{name="air", prob=0, param2=0},
		{name="air", prob=0, param2=0},
		{name="air", prob=0, param2=0},
		{name="air", prob=0, param2=0},
		{name="air", prob=0, param2=0},
		{name="air", prob=0, param2=0},
		{name="air", prob=0, param2=0},
		{name="air", prob=0, param2=0},
		{name="air", prob=0, param2=0},
		{name="air", prob=0, param2=0},
		{name="air", prob=0, param2=0},
		{name="air", prob=0, param2=0},
		{name="air", prob=0, param2=0},
		{name="air", prob=0, param2=0},
		{name="air", prob=0, param2=0},
		{name="mini_nodes:oak_leaves", prob=128, param2=0},
		{name="mini_nodes:apple_leaves", prob=128, param2=0},
		{name="mini_nodes:oak_leaves", prob=128, param2=0},
		{name="air", prob=0, param2=0},
		{name="air", prob=0, param2=0},
		{name="air", prob=0, param2=0},
		{name="air", prob=0, param2=0},
		{name="air", prob=0, param2=0},
		{name="air", prob=0, param2=0},
		{name="air", prob=0, param2=0},
		{name="mini_nodes:apple_leaves", prob=128, param2=0},
		{name="mini_nodes:oak_leaves", prob=254, param2=0},
		{name="mini_nodes:oak_leaves", prob=254, param2=0},
		{name="mini_nodes:oak_leaves", prob=254, param2=0},
		{name="mini_nodes:oak_leaves", prob=128, param2=0},
		{name="air", prob=0, param2=0},
		{name="air", prob=0, param2=0},
		{name="air", prob=0, param2=0},
		{name="air", prob=0, param2=0},
		{name="air", prob=0, param2=0},
		{name="air", prob=0, param2=0},
		{name="mini_nodes:oak_leaves", prob=128, param2=0},
		{name="mini_nodes:oak_leaves", prob=128, param2=0},
		{name="mini_nodes:oak_leaves", prob=254, param2=0},
		{name="mini_nodes:oak_leaves", prob=254, param2=0},
		{name="mini_nodes:oak_leaves", prob=128, param2=0},
		{name="air", prob=0, param2=0},
		{name="air", prob=0, param2=0},
		{name="air", prob=0, param2=0},
		{name="air", prob=0, param2=0},
		{name="air", prob=0, param2=0},
		{name="air", prob=0, param2=0},
		{name="air", prob=0, param2=0},
		{name="mini_nodes:oak_leaves", prob=128, param2=0},
		{name="mini_nodes:oak_leaves", prob=128, param2=0},
		{name="mini_nodes:oak_leaves", prob=128, param2=0},
		{name="air", prob=0, param2=0},
		{name="air", prob=0, param2=0},
		{name="air", prob=0, param2=0},
		{name="air", prob=0, param2=0},
		{name="air", prob=0, param2=0},
		{name="air", prob=0, param2=0},
		{name="air", prob=0, param2=0},
		{name="air", prob=0, param2=0},
		{name="air", prob=0, param2=0},
		{name="air", prob=0, param2=0},
		{name="air", prob=0, param2=0},
		{name="air", prob=0, param2=0},
		{name="air", prob=0, param2=0},
		{name="air", prob=0, param2=0},
		{name="air", prob=0, param2=0},
		{name="air", prob=0, param2=0},
		{name="air", prob=0, param2=0},
		{name="air", prob=0, param2=0},
		{name="air", prob=0, param2=0},
		{name="air", prob=0, param2=0},
		{name="air", prob=0, param2=0},
		{name="air", prob=0, param2=0},
		{name="air", prob=0, param2=0},
		{name="air", prob=0, param2=0},
		{name="air", prob=0, param2=0},
		{name="air", prob=0, param2=0},
		{name="air", prob=0, param2=0},
		{name="air", prob=0, param2=0},
		{name="air", prob=0, param2=0},
		{name="air", prob=0, param2=0},
		{name="air", prob=0, param2=0},
		{name="air", prob=0, param2=0},
		{name="air", prob=0, param2=0},
		{name="air", prob=0, param2=0},
		{name="air", prob=0, param2=0},
		{name="air", prob=0, param2=0},
		{name="air", prob=0, param2=0},
		{name="air", prob=0, param2=0},
		{name="air", prob=0, param2=0},
		{name="air", prob=0, param2=0},
		{name="air", prob=0, param2=0},
		{name="air", prob=0, param2=0},
		{name="air", prob=0, param2=0},
		{name="air", prob=0, param2=0},
		{name="air", prob=0, param2=0},
		{name="air", prob=0, param2=0},
		{name="air", prob=0, param2=0},
		{name="air", prob=0, param2=0},
		{name="air", prob=0, param2=0},
		{name="air", prob=0, param2=0},
		{name="air", prob=0, param2=0},
		{name="air", prob=0, param2=0},
		{name="air", prob=0, param2=0},
		{name="air", prob=0, param2=0},
		{name="air", prob=0, param2=0},
		{name="air", prob=0, param2=0},
		{name="air", prob=0, param2=0},
		{name="air", prob=0, param2=0},
		{name="air", prob=0, param2=0},
		{name="air", prob=0, param2=0},
		{name="air", prob=0, param2=0},
		{name="air", prob=0, param2=0},
		{name="air", prob=0, param2=0},
		{name="air", prob=0, param2=0},
		{name="air", prob=0, param2=0},
		{name="air", prob=0, param2=0},
		{name="air", prob=0, param2=0},
		{name="air", prob=0, param2=0},
		{name="air", prob=0, param2=0},
		{name="air", prob=0, param2=0},
		{name="air", prob=0, param2=0},
		{name="air", prob=0, param2=0},
		{name="air", prob=0, param2=0},
		{name="air", prob=0, param2=0},
		{name="air", prob=0, param2=0},
		{name="air", prob=0, param2=0},
		{name="air", prob=0, param2=0},
		{name="air", prob=0, param2=0},
		{name="air", prob=0, param2=0},
		{name="air", prob=0, param2=0},
		{name="air", prob=0, param2=0},
		{name="air", prob=0, param2=0},
		{name="air", prob=0, param2=0},
		{name="air", prob=0, param2=0},
		{name="air", prob=0, param2=0},
		{name="air", prob=0, param2=0},
		{name="air", prob=0, param2=0},
		{name="air", prob=0, param2=0},
		{name="air", prob=0, param2=0},
		{name="air", prob=0, param2=0},
		{name="air", prob=0, param2=0},
		{name="air", prob=0, param2=0},
		{name="air", prob=0, param2=0},
		{name="air", prob=0, param2=0},
		{name="air", prob=0, param2=0},
		{name="air", prob=0, param2=0},
		{name="air", prob=0, param2=0},
		{name="air", prob=0, param2=0},
		{name="air", prob=0, param2=0},
		{name="air", prob=0, param2=0},
		{name="air", prob=0, param2=0},
		{name="air", prob=0, param2=0},
		{name="air", prob=0, param2=0},
		{name="air", prob=0, param2=0},
		{name="air", prob=0, param2=0},
		{name="air", prob=0, param2=0},
		{name="air", prob=0, param2=0},
		{name="mini_nodes:oak_leaves", prob=128, param2=0},
		{name="mini_nodes:oak_leaves", prob=128, param2=0},
		{name="mini_nodes:oak_leaves", prob=128, param2=0},
		{name="air", prob=0, param2=0},
		{name="air", prob=0, param2=0},
		{name="air", prob=0, param2=0},
		{name="air", prob=0, param2=0},
		{name="air", prob=0, param2=0},
		{name="air", prob=0, param2=0},
		{name="air", prob=0, param2=0},
		{name="air", prob=0, param2=0},
		{name="air", prob=0, param2=0},
		{name="mini_nodes:oak_leaves", prob=128, param2=0},
		{name="mini_nodes:oak_leaves", prob=128, param2=0},
		{name="air", prob=0, param2=0},
		{name="air", prob=0, param2=0},
		{name="air", prob=0, param2=0},
		{name="air", prob=0, param2=0},
		{name="air", prob=0, param2=0},
		{name="air", prob=0, param2=0},
		{name="air", prob=0, param2=0},
		{name="air", prob=0, param2=0},
		{name="air", prob=0, param2=0},
		{name="air", prob=0, param2=0},
		{name="air", prob=0, param2=0},
		{name="air", prob=0, param2=0},
		{name="air", prob=0, param2=0},
		{name="air", prob=0, param2=0},
		{name="air", prob=0, param2=0},
		{name="air", prob=0, param2=0},
		{name="air", prob=0, param2=0},
		{name="air", prob=0, param2=0},
		{name="air", prob=0, param2=0},
		{name="air", prob=0, param2=0},
		{name="air", prob=0, param2=0},
		{name="air", prob=0, param2=0},
		{name="air", prob=0, param2=0},
		{name="air", prob=0, param2=0},
		{name="air", prob=0, param2=0},
		{name="air", prob=0, param2=0},
		{name="air", prob=0, param2=0},
		{name="air", prob=0, param2=0},
		{name="air", prob=0, param2=0},
		{name="air", prob=0, param2=0},
		{name="air", prob=0, param2=0},
		{name="air", prob=0, param2=0},
		{name="air", prob=0, param2=0},
		{name="air", prob=0, param2=0},
		{name="air", prob=0, param2=0},
		{name="air", prob=0, param2=0},
		{name="air", prob=0, param2=0},
	},
}
